### version information

```
pre-commit version: 3.6.0
git --version: git version 2.43.0.windows.1
sys.version:
    3.11.5 | packaged by Anaconda, Inc. | (main, Sep 11 2023, 13:26:23) [MSC v.1916 64 bit (AMD64)]
sys.executable: C:\Users\sapd\AppData\Local\anaconda3\python.exe
os.name: nt
sys.platform: win32
```

### error information

```
An error has occurred: InvalidConfigError: 
==> File .pre-commit-config.yaml
=====> while scanning a simple key
  in "<unicode string>", line 30, column 1
could not find expected ':'
  in "<unicode string>", line 31, column 1
```

```
Traceback (most recent call last):
  File "C:\Users\sapd\AppData\Local\anaconda3\Lib\site-packages\pre_commit\error_handler.py", line 73, in error_handler
    yield
  File "C:\Users\sapd\AppData\Local\anaconda3\Lib\site-packages\pre_commit\main.py", line 414, in main
    return run(args.config, store, args)
           ^^^^^^^^^^^^^^^^^^^^^^^^^^^^^
  File "C:\Users\sapd\AppData\Local\anaconda3\Lib\site-packages\pre_commit\commands\run.py", line 422, in run
    config = load_config(config_file)
             ^^^^^^^^^^^^^^^^^^^^^^^^
  File "C:\Users\sapd\AppData\Local\anaconda3\Lib\site-packages\cfgv.py", line 399, in load_from_filename
    with reraise_as(exc_tp):
  File "C:\Users\sapd\AppData\Local\anaconda3\Lib\contextlib.py", line 155, in __exit__
    self.gen.throw(typ, value, traceback)
  File "C:\Users\sapd\AppData\Local\anaconda3\Lib\site-packages\cfgv.py", line 45, in reraise_as
    raise tp(e).with_traceback(tb) from None
  File "C:\Users\sapd\AppData\Local\anaconda3\Lib\site-packages\cfgv.py", line 42, in reraise_as
    yield
  File "C:\Users\sapd\AppData\Local\anaconda3\Lib\site-packages\cfgv.py", line 403, in load_from_filename
    with validate_context(f'File {display_filename}'):
  File "C:\Users\sapd\AppData\Local\anaconda3\Lib\contextlib.py", line 155, in __exit__
    self.gen.throw(typ, value, traceback)
  File "C:\Users\sapd\AppData\Local\anaconda3\Lib\site-packages\cfgv.py", line 36, in validate_context
    raise ValidationError(e, ctx=msg).with_traceback(tb) from None
  File "C:\Users\sapd\AppData\Local\anaconda3\Lib\site-packages\cfgv.py", line 33, in validate_context
    yield
  File "C:\Users\sapd\AppData\Local\anaconda3\Lib\site-packages\cfgv.py", line 413, in load_from_filename
    raise ValidationError(str(e))
pre_commit.clientlib.InvalidConfigError: 
==> File .pre-commit-config.yaml
=====> while scanning a simple key
  in "<unicode string>", line 30, column 1
could not find expected ':'
  in "<unicode string>", line 31, column 1
```
